Traceback (most recent call last):
  File "/home/tom/miniconda3/envs/sim/lib/python3.9/site-packages/jupyter_cache/executors/utils.py", line 58, in single_nb_execution
    executenb(
  File "/home/tom/miniconda3/envs/sim/lib/python3.9/site-packages/nbclient/client.py", line 1305, in execute
    return NotebookClient(nb=nb, resources=resources, km=km, **kwargs).execute()
  File "/home/tom/miniconda3/envs/sim/lib/python3.9/site-packages/jupyter_core/utils/__init__.py", line 166, in wrapped
    return loop.run_until_complete(inner)
  File "/home/tom/miniconda3/envs/sim/lib/python3.9/asyncio/base_events.py", line 647, in run_until_complete
    return future.result()
  File "/home/tom/miniconda3/envs/sim/lib/python3.9/site-packages/nbclient/client.py", line 705, in async_execute
    await self.async_execute_cell(
  File "/home/tom/miniconda3/envs/sim/lib/python3.9/site-packages/nbclient/client.py", line 1058, in async_execute_cell
    await self._check_raise_for_error(cell, cell_index, exec_reply)
  File "/home/tom/miniconda3/envs/sim/lib/python3.9/site-packages/nbclient/client.py", line 914, in _check_raise_for_error
    raise CellExecutionError.from_cell_and_msg(cell, exec_reply_content)
nbclient.exceptions.CellExecutionError: An error occurred while executing the following cell:
------------------
# test of the function

# assume code is run in same directory as example csv file
df_experiment = pd.read_csv('example_experiments.csv')

experiments_to_run = create_experiments(df_experiment)

print(type(experiments_to_run))

print(experiments_to_run['base'].n_nurses)
------------------


[0;31m---------------------------------------------------------------------------[0m
[0;31mTypeError[0m                                 Traceback (most recent call last)
Cell [0;32mIn[6], line 6[0m
[1;32m      1[0m [38;5;66;03m# test of the function[39;00m
[1;32m      2[0m 
[1;32m      3[0m [38;5;66;03m# assume code is run in same directory as example csv file[39;00m
[1;32m      4[0m df_experiment [38;5;241m=[39m pd[38;5;241m.[39mread_csv([38;5;124m'[39m[38;5;124mexample_experiments.csv[39m[38;5;124m'[39m)
[0;32m----> 6[0m experiments_to_run [38;5;241m=[39m [43mcreate_experiments[49m[43m([49m[43mdf_experiment[49m[43m)[49m
[1;32m      8[0m [38;5;28mprint[39m([38;5;28mtype[39m(experiments_to_run))
[1;32m     10[0m [38;5;28mprint[39m(experiments_to_run[[38;5;124m'[39m[38;5;124mbase[39m[38;5;124m'[39m][38;5;241m.[39mn_nurses)

Cell [0;32mIn[5], line 24[0m, in [0;36mcreate_experiments[0;34m(df_experiments)[0m
[1;32m     22[0m [38;5;66;03m# loop through params and create Experiment objects.[39;00m
[1;32m     23[0m [38;5;28;01mfor[39;00m name, params [38;5;129;01min[39;00m [38;5;28mzip[39m(exp_names, exp_dict[38;5;241m.[39mvalues()):
[0;32m---> 24[0m     experiments[name] [38;5;241m=[39m [43mExperiment[49m[43m([49m[38;5;241;43m*[39;49m[38;5;241;43m*[39;49m[43mparams[49m[43m)[49m
[1;32m     26[0m [38;5;28;01mreturn[39;00m experiments

[0;31mTypeError[0m: __init__() got an unexpected keyword argument 'experiment'

